Workbook
Name Slicer_Cancer_History: #N/A
Name Slicer_Diabetes_Status: #N/A
Name Slicer_Number_of_major_Surgeries: #N/A
Name Slicer_Smoker: #N/A
Name Slicer_Weight_Status: #N/A

Sheet Observation
A1: Data Cleaning
A2: Items | B2: Customer name | C2: Medical Examination | D2: Hospitalisation | E2: 1) Check for the number of missing values marked with '?' in each column of the "Medical Examinations" table and "Hospitalization Details" table. 2) Fill in the missing values of ‘month’ with Sep and ‘year’ with its average, rounded to the nearest integer. 3) Determine the most frequently occurring values in the ‘smoker’, 'hospital tier', and 'city tier' columns, and fill in the missing values accordingly. 4) If any 'State ID' values are missing, consider filling them with 'Unknown' or using another appropriate strategy.
A3: id | D3: ?=6
A4: customer name
A5: BMI
A6: HBA1C
A7: Heart Issues
A8: Any Transplants
A9: Cancer history
A10: NumberOfMajorSurgeries
A11: smoker | C11: ? =2
A12: year | D12: ?=2
A13: month | D13: ?=3
A14: date
A15: children
A16: charges
A17: Hospital tier | D17: ?=1
A18: City tier | D18: ?=1
A19: State ID | D19: ?=2
A20: Data Transformation
A21: 1) Split the ‘names’ column in the “Customer Names” table into 3 meaningful columns: ‘Title’, ‘First Name’, and ‘Last Name’. 2) Convert the "NumberOfMajorSurgeries" column in the "Medical Examinations" table to numerical data by replacing non-numeric characters with meaningful numerical values. 3) Check for inconsistencies in the 'Heart Issues' and 'Smoker' columns and propose corrective actions if necessary. 4) Create a new column named “Weight Status” that categorizes BMI into different categories as below: BMI Weight Status Below 18.5 Underweight 18.5 – 24.9 Normal Weight 25.0 – 29.9 Overweight 30.0 and Above Obesity 5) Merge the ‘year’, ‘month’, and ‘date’ columns in the “Hospitalization Details” table into one column named ‘Date of Birth’ and format it in the ‘DD-MMM-YYYY’ custom format. 7) Calculate the ‘Age’ of each customer based on their ‘Date of Birth’ and the date of collection of the dataset, which is 8th June 2023. 8) Format the ‘charges’ column as currency ($).
A48: AI-Driven Data Exploration, Analysis & Visualization
A49: Activity 1: Data Preparation – (2 marks) (should be done manually) ➢ Create a new sheet named “Healthcare”, and combine all three tables into one, using Customer ID as the common column, utilizing XLOOKUP/Data Model manager. ➢ Retain the following necessary columns: Customer ID, First Name, BMI, HBA1C, Heart Issues, Any Transplants, Cancer History, Number of Major Surgeries, Smoker, Weight Status, Diabetes Status, Date of Birth, Charges, Hospital Tier, City Tier, State ID, and Age. Activity 2: Manual Dashboard Build (5 marks) (should be done manually) ● Create a pivot table manually (Insert → PivotTable) using the combined healthcare dataset. ● Add charts: ○ Pie/Donut Chart: Cancer history distribution among smokers vs non-smokers. ○ Column Chart: Charges by Weight Status. ● Draw the insight manually and marked it down in the sheet Activity 2: AI-Powered Summary Statistics & Visualization( 5 marks) (AI-driven task) Automatically generate and visualize overall healthcare statistics. 1. Highlight the combined dataset (new sheet named “Healthcare”). 2. Use Quick Analysis→ to calculate dynamic counts and averages ● Total customers count, ● Total hospitalisation count, ● Total healthcare costs, ● Average costs and medical metrics 3. Use Quick Analysis → Recommended Charts (Column/Bar/Doughnut) to visualise distributions of all pivots created in the previous step using AI tools. ● Expected Output: ○ Pivot chart/quick analysis chart visualising totals. Activity 4: Dashboard Creation (3 marks) ● Build an interactive dashboard that consolidates all key insights using the above visualisations. Ensure visual clarity and ease of interpretation for all chart types. ● Insert slicers for weight status and diabetes status, and wherever possible. ● Arrange charts and slicers into a simple dashboard layout ● Add a heading (e.g., Healthcare Dashboard – AI Analysis). ● Ensure consistency in chart formatting for clear interpretation.

Sheet Customer Names Cleaning
C1: Use Text to Column
A2: Customer ID | B2: name | C2: Last Name | D2: Title | E2: First Name
A3: Id1 | B3: Hawks, Ms. Kelly | C3: Hawks | D3: Ms. | E3: Kelly | F3: =IF(RIGHT(E3,1)=".",LEFT(E3,LEN(E3)-1),E3) -> Kelly
A4: Id2 | B4: Lehner, Mr. Matthew D | C4: Lehner | D4: Mr. | E4: Matthew D | F4: =IF(RIGHT(E4,1)=".",LEFT(E4,LEN(E4)-1),E4) -> Matthew D
A5: Id3 | B5: Lu, Mr. Phil | C5: Lu | D5: Mr. | E5: Phil | F5: =IF(RIGHT(E5,1)=".",LEFT(E5,LEN(E5)-1),E5) -> Phil
A6: Id4 | B6: Osborne, Ms. Kelsey | C6: Osborne | D6: Ms. | E6: Kelsey | F6: =IF(RIGHT(E6,1)=".",LEFT(E6,LEN(E6)-1),E6) -> Kelsey
A7: Id5 | B7: Kadala, Ms. Kristyn | C7: Kadala | D7: Ms. | E7: Kristyn | F7: =IF(RIGHT(E7,1)=".",LEFT(E7,LEN(E7)-1),E7) -> Kristyn
A8: Id6 | B8: Baker, Mr. Russell B. | C8: Baker | D8: Mr. | E8: Russell B. | F8: =IF(RIGHT(E8,1)=".",LEFT(E8,LEN(E8)-1),E8) -> Russell B
A9: Id7 | B9: Macpherson, Mr. Scott | C9: Macpherson | D9: Mr. | E9: Scott | F9: =IF(RIGHT(E9,1)=".",LEFT(E9,LEN(E9)-1),E9) -> Scott
A10: Id8 | B10: Hallman, Mr. Stephen | C10: Hallman | D10: Mr. | E10: Stephen | F10: =IF(RIGHT(E10,1)=".",LEFT(E10,LEN(E10)-1),E10) -> Stephen
A11: Id9 | B11: Moran, Mr. Patrick R. | C11: Moran | D11: Mr. | E11: Patrick R. | F11: =IF(RIGHT(E11,1)=".",LEFT(E11,LEN(E11)-1),E11) -> Patrick R
A12: Id10 | B12: Benner, Ms. Brooke N. | C12: Benner | D12: Ms. | E12: Brooke N. | F12: =IF(RIGHT(E12,1)=".",LEFT(E12,LEN(E12)-1),E12) -> Brooke N
A13: Id11 | B13: Fierro Vargas, Ms. Paola Andrea | C13: Fierro Vargas | D13: Ms. | E13: Paola Andrea | F13: =IF(RIGHT(E13,1)=".",LEFT(E13,LEN(E13)-1),E13) -> Paola Andrea
A14: Id12 | B14: Franz, Mr. David | C14: Franz | D14: Mr. | E14: David | F14: =IF(RIGHT(E14,1)=".",LEFT(E14,LEN(E14)-1),E14) -> David
... A2337: Id2335 | B2337: German, Mr. Aaron K | C2337: German | D2337: Mr. | E2337: Aaron K | F2337: =IF(RIGHT(E2337,1)=".",LEFT(E2337,LEN(E2337)-1),E2337) -> Aaron K
A2338: =COUNTA(A3:A2337) -> 2335

Sheet Medical Examinations Cleaning
I1: MATCH($H$3:$H$2337,$H$3:$H$2337,0) | J1: IF(H3="?",INDEX($H$3:$H$2337,MODE($I$3:$I$2337)),H3) | K1: IF(G3="No major surgery",0,G3) | L1: Proper | N1: Change Number format | O1: IFS(N3<18.5,"Underweight",N3<25,"Normalweight",N3<30,"Overweight",N3>=30,"Obesity")
A2: Customer ID | B2: BMI | C2: HBA1C | D2: Heart Issues | E2: Any Transplants | F2: Cancer history | G2: NumberOfMajorSurgeries | H2: smoker | I2: Smoker Encoding | J2: Smoker | K2: NumberOfMajorSurgeries | L2: Smoker | M2: Heart Issues | N2: BMI | O2: Weight Status | P2: Customer ID | Q2: BMI | R2: HBA1C | S2: Heart Issues | T2: Any Transplants | U2: Cancer history | V2: NumberOfMajorSurgeries | W2: smoker | X2: Weight Status | Y2: Diabetes Status
A3: Id1 | B3: 47.41 | C3: 7.47 | D3: No | E3: No | F3: No | G3: No major surgery | H3: yes | I3: {=MATCH($H$3:$H$2337,$H$3:$H$2337,0)} -> 1 | J3: {=IF(H3="?",INDEX($H$3:$H$2337,MODE($I$3:$I$2337)),H3)} -> yes | K3: =IF(G3="No major surgery",0,G3) -> 0 | L3: =PROPER(J3) -> Yes | M3: =PROPER(D3) -> No | N3: 47.41 | O3: {=_xlfn.IFS(N3<18.5,"Underweight",N3<25,"Normalweight",N3<30,"Overweight",N3>=30,"Obesity")} -> Obesity | P3: Id1 | Q3: 47.41 | R3: 7.47 | S3: No | T3: No | U3: No | V3: 0 | W3: Yes | X3: Obesity | Y3: =IF(R32<=5.7,"Normal",IF(R3<=6.5,"Prediabetes","Diabetes")) -> Diabetes
A4: Id2 | B4: 30.36 | C4: 5.77 | D4: No | E4: No | F4: No | G4: No major surgery | H4: yes | I4: 1 | J4: =IF(H4="?",INDEX($H$3:$H$2337,MODE($I$3:$I$2337)),H4) -> yes | K4: =IF(G4="No major surgery",0,G4) -> 0 | L4: =PROPER(J4) -> Yes | M4: =PROPER(D4) -> No | N4: 30.36 | O4: {=_xlfn.IFS(N4<18.5,"Underweight",N4<25,"Normalweight",N4<30,"Overweight",N4>=30,"Obesity")} -> Obesity | P4: Id2 | Q4: 30.36 | R4: 5.77 | S4: No | T4: No | U4: No | V4: 0 | W4: Yes | X4: Obesity | Y4: =IF(R33<=5.7,"Normal",IF(R4<=6.5,"Prediabetes","Diabetes")) -> Prediabetes
A5: Id3 | B5: 34.485 | C5: 11.87 | D5: yes | E5: No | F5: No | G5: 2 | H5: yes | I5: 1 | J5: =IF(H5="?",INDEX($H$3:$H$2337,MODE($I$3:$I$2337)),H5) -> yes | K5: =IF(G5="No major surgery",0,G5) -> 2 | L5: =PROPER(J5) -> Yes | M5: =PROPER(D5) -> Yes | N5: 34.485 | O5: {=_xlfn.IFS(N5<18.5,"Underweight",N5<25,"Normalweight",N5<30,"Overweight",N5>=30,"Obesity")} -> Obesity | P5: Id3 | Q5: 34.485 | R5: 11.87 | S5: Yes | T5: No | U5: No | V5: 2 | W5: Yes | X5: Obesity | Y5: =IF(R34<=5.7,"Normal",IF(R5<=6.5,"Prediabetes","Diabetes")) -> Normal
A6: Id4 | B6: 38.095 | C6: 6.05 | D6: No | E6: No | F6: No | G6: No major surgery | H6: yes | I6: 1 | J6: =IF(H6="?",INDEX($H$3:$H$2337,MODE($I$3:$I$2337)),H6) -> yes | K6: =IF(G6="No major surgery",0,G6) -> 0 | L6: =PROPER(J6) -> Yes | M6: =PROPER(D6) -> No | N6: 38.095 | O6: {=_xlfn.IFS(N6<18.5,"Underweight",N6<25,"Normalweight",N6<30,"Overweight",N6>=30,"Obesity")} -> Obesity | P6: Id4 | Q6: 38.095 | R6: 6.05 | S6: No | T6: No | U6: No | V6: 0 | W6: Yes | X6: Obesity | Y6: =IF(R35<=5.7,"Normal",IF(R6<=6.5,"Prediabetes","Diabetes")) -> Prediabetes
A7: Id5 | B7: 35.53 | C7: 5.45 | D7: No | E7: No | F7: No | G7: No major surgery | H7: yes | I7: 1 | J7: =IF(H7="?",INDEX($H$3:$H$2337,MODE($I$3:$I$2337)),H7) -> yes | K7: =IF(G7="No major surgery",0,G7) -> 0 | L7: =PROPER(J7) -> Yes | M7: =PROPER(D7) -> No | N7: 35.53 | O7: {=_xlfn.IFS(N7<18.5,"Underweight",N7<25,"Normalweight",N7<30,"Overweight",N7>=30,"Obesity")} -> Obesity | P7: Id5 | Q7: 35.53 | R7: 5.45 | S7: No | T7: No | U7: No | V7: 0 | W7: Yes | X7: Obesity | Y7: =IF(R36<=5.7,"Normal",IF(R7<=6.5,"Prediabetes","Diabetes")) -> Prediabetes
A8: Id6 | B8: 32.8 | C8: 6.59 | D8: No | E8: No | F8: No | G8: No major surgery | H8: yes | I8: 1 | J8: =IF(H8="?",INDEX($H$3:$H$2337,MODE($I$3:$I$2337)),H8) -> yes | K8: =IF(G8="No major surgery",0,G8) -> 0 | L8: =PROPER(J8) -> Yes | M8: =PROPER(D8) -> No | N8: 32.8 | O8: {=_xlfn.IFS(N8<18.5,"Underweight",N8<25,"Normalweight",N8<30,"Overweight",N8>=30,"Obesity")} -> Obesity | P8: Id6 | Q8: 32.8 | R8: 6.59 | S8: No | T8: No | U8: No | V8: 0 | W8: Yes | X8: Obesity | Y8: =IF(R37<=5.7,"Normal",IF(R8<=6.5,"Prediabetes","Diabetes")) -> Diabetes
A9: Id7 | B9: 36.4 | C9: 6.07 | D9: No | E9: No | F9: No | G9: No major surgery | H9: yes | I9: 1 | J9: =IF(H9="?",INDEX($H$3:$H$2337,MODE($I$3:$I$2337)),H9) -> yes | K9: =IF(G9="No major surgery",0,G9) -> 0 | L9: =PROPER(J9) -> Yes | M9: =PROPER(D9) -> No | N9: 36.4 | O9: {=_xlfn.IFS(N9<18.5,"Underweight",N9<25,"Normalweight",N9<30,"Overweight",N9>=30,"Obesity")} -> Obesity | P9: Id7 | Q9: 36.4 | R9: 6.07 | S9: No | T9: No | U9: No | V9: 0 | W9: Yes | X9: Obesity | Y9: =IF(R38<=5.7,"Normal",IF(R9<=6.5,"Prediabetes","Diabetes")) -> Prediabetes
A10: Id8 | B10: 36.96 | C10: 7.93 | D10: No | E10: No | F10: No | G10: 3 | H10: yes | I10: 1 | J10: =IF(H10="?",INDEX($H$3:$H$2337,MODE($I$3:$I$2337)),H10) -> yes | K10: =IF(G10="No major surgery",0,G10) -> 3 | L10: =PROPER(J10) -> Yes | M10: =PROPER(D10) -> No | N10: 36.96 | O10: {=_xlfn.IFS(N10<18.5,"Underweight",N10<25,"Normalweight",N10<30,"Overweight",N10>=30,"Obesity")} -> Obesity | P10: Id8 | Q10: 36.96 | R10: 7.93 | S10: No | T10: No | U10: No | V10: 3 | W10: Yes | X10: Obesity | Y10: =IF(R39<=5.7,"Normal",IF(R10<=6.5,"Prediabetes","Diabetes")) -> Diabetes
A11: Id9 | B11: 41.14 | C11: 9.58 | D11: yes | E11: No | F11: Yes | G11: 1 | H11: yes | I11: 1 | J11: =IF(H11="?",INDEX($H$3:$H$2337,MODE($I$3:$I$2337)),H11) -> yes | K11: =IF(G11="No major surgery",0,G11) -> 1 | L11: =PROPER(J11) -> Yes | M11: =PROPER(D11) -> Yes | N11: 41.14 | O11: {=_xlfn.IFS(N11<18.5,"Underweight",N11<25,"Normalweight",N11<30,"Overweight",N11>=30,"Obesity")} -> Obesity | P11: Id9 | Q11: 41.14 | R11: 9.58 | S11: Yes | T11: No | U11: Yes | V11: 1 | W11: Yes | X11: Obesity | Y11: =IF(R40<=5.7,"Normal",IF(R11<=6.5,"Prediabetes","Diabetes")) -> Diabetes
A12: Id10 | B12: 38.06 | C12: 10.79 | D12: No | E12: No | F12: No | G12: No major surgery | H12: yes | I12: 1 | J12: =IF(H12="?",INDEX($H$3:$H$2337,MODE($I$3:$I$2337)),H12) -> yes | K12: =IF(G12="No major surgery",0,G12) -> 0 | L12: =PROPER(J12) -> Yes | M12: =PROPER(D12) -> No | N12: 38.06 | O12: {=_xlfn.IFS(N12<18.5,"Underweight",N12<25,"Normalweight",N12<30,"Overweight",N12>=30,"Obesity")} -> Obesity | P12: Id10 | Q12: 38.06 | R12: 10.79 | S12: No | T12: No | U12: No | V12: 0 | W12: Yes | X12: Obesity | Y12: =IF(R41<=5.7,"Normal",IF(R12<=6.5,"Prediabetes","Diabetes")) -> Diabetes
A13: Id11 | B13: 37.7 | C13: 5.96 | D13: yes | E13: No | F13: No | G13: 2 | H13: yes | I13: 1 | J13: =IF(H13="?",INDEX($H$3:$H$2337,MODE($I$3:$I$2337)),H13) -> yes | K13: =IF(G13="No major surgery",0,G13) -> 2 | L13: =PROPER(J13) -> Yes | M13: =PROPER(D13) -> Yes | N13: 37.7 | O13: {=_xlfn.IFS(N13<18.5,"Underweight",N13<25,"Normalweight",N13<30,"Overweight",N13>=30,"Obesity")} -> Obesity | P13: Id11 | Q13: 37.7 | R13: 5.96 | S13: Yes | T13: No | U13: No | V13: 2 | W13: Yes | X13: Obesity | Y13: =IF(R42<=5.7,"Normal",IF(R13<=6.5,"Prediabetes","Diabetes")) -> Normal
A14: Id12 | B14: 42.13 | C14: 11.9 | D14: No | E14: No | F14: No | G14: No major surgery | H14: yes | I14: 1 | J14: =IF(H14="?",INDEX($H$3:$H$2337,MODE($I$3:$I$2337)),H14) -> yes | K14: =IF(G14="No major surgery",0,G14) -> 0 | L14: =PROPER(J14) -> Yes | M14: =PROPER(D14) -> No | N14: 42.13 | O14: {=_xlfn.IFS(N14<18.5,"Underweight",N14<25,"Normalweight",N14<30,"Overweight",N14>=30,"Obesity")} -> Obesity | P14: Id12 | Q14: 42.13 | R14: 11.9 | S14: No | T14: No | U14: No | V14: 0 | W14: Yes | X14: Obesity | Y14: =IF(R43<=5.7,"Normal",IF(R14<=6.5,"Prediabetes","Diabetes")) -> Normal
A15: Id13 | B15: 40.92 | C15: 8.41 | D15: No | E15: No | F15: No | G15: No major surgery | H15: yes | I15: 1 | J15: =IF(H15="?",INDEX($H$3:$H$2337,MODE($I$3:$I$2337)),H15) -> yes | K15: =IF(G15="No major surgery",0,G15) -> 0 | L15: =PROPER(J15) -> Yes | M15: =PROPER(D15) -> No | N15: 40.92 | O15: {=_xlfn.IFS(N15<18.5,"Underweight",N15<25,"Normalweight",N15<30,"Overweight",N15>=30,"Obesity")} -> Obesity | P15: Id13 | Q15: 40.92 | R15: 8.41 | S15: No | T15: No | U15: No | V15: 0 | W15: Yes | X15: Obesity | Y15: =IF(R44<=5.7,"Normal",IF(R15<=6.5,"Prediabetes","Diabetes")) -> Diabetes
A16: Id14 | B16: 40.565 | C16: 7.02 | D16: No | E16: No | F16: No | G16: No major surgery | H16: yes | I16: 1 | J16: =IF(H16="?",INDEX($H$3:$H$2337,MODE($I$3:$I$2337)),H16) -> yes | K16: =IF(G16="No major surgery",0,G16) -> 0 | L16: =PROPER(J16) -> Yes | M16: =PROPER(D16) -> No | N16: 40.565 | O16: {=_xlfn.IFS(N16<18.5,"Underweight",N16<25,"Normalweight",N16<30,"Overweight",N16>=30,"Obesity")} -> Obesity | P16: Id14 | Q16: 40.565 | R16: 7.02 | S16: No | T16: No | U16: No | V16: 0 | W16: Yes | X16: Obesity | Y16: =IF(R45<=5.7,"Normal",IF(R16<=6.5,"Prediabetes","Diabetes")) -> Diabetes
A17: Id15 | B17: 36.385 | C17: 7.59 | D17: yes | E17: No | F17: No | G17: 2 | H17: yes | I17: 1 | J17: =IF(H17="?",INDEX($H$3:$H$2337,MODE($I$3:$I$2337)),H17) -> yes | K17: =IF(G17="No major surgery",0,G17) -> 2 | L17: =PROPER(J17) -> Yes | M17: =PROPER(D17) -> Yes | N17: 36.385 | O17: {=_xlfn.IFS(N17<18.5,"Underweight",N17<25,"Normalweight",N17<30,"Overweight",N17>=30,"Obesity")} -> Obesity | P17: Id15 | Q17: 36.385 | R17: 7.59 | S17: Yes | T17: No | U17: No | V17: 2 | W17: Yes | X17: Obesity | Y17: =IF(R46<=5.7,"Normal",IF(R17<=6.5,"Prediabetes","Diabetes")) -> Diabetes
A18: Id16 | B18: 39.9 | C18: 11.32 | D18: No | E18: No | F18: No | G18: No major surgery | H18: yes | I18: 1 | J18: =IF(H18="?",INDEX($H$3:$H$2337,MODE($I$3:$I$2337)),H18) -> yes | K18: =IF(G18="No major surgery",0,G18) -> 0 | L18: =PROPER(J18) -> Yes | M18: =PROPER(D18) -> No | N18: 39.9 | O18: {=_xlfn.IFS(N18<18.5,"Underweight",N18<25,"Normalweight",N18<30,"Overweight",N18>=30,"Obesity")} -> Obesity | P18: Id16 | Q18: 39.9 | R18: 11.32 | S18: No | T18: No | U18: No | V18: 0 | W18: Yes | X18: Obesity | Y18: =IF(R47<=5.7,"Normal",IF(R18<=6.5,"Prediabetes","Diabetes")) -> Diabetes
A19: Id17 | B19: 33.8 | C19: 7.67 | D19: No | E19: No | F19: No | G19: 3 | H19: yes | I19: 1 | J19: =IF(H19="?",INDEX($H$3:$H$2337,MODE($I$3:$I$2337)),H19) -> yes | K19: =IF(G19="No major surgery",0,G19) -> 3 | L19: =PROPER(J19) -> Yes | M19: =PROPER(D19) -> No | N19: 33.8 | O19: {=_xlfn.IFS(N19<18.5,"Underweight",N19<25,"Normalweight",N19<30,"Overweight",N19>=30,"Obesity")} -> Obesity | P19: Id17 | Q19: 33.8 | R19: 7.67 | S19: No | T19: No | U19: No | V19: 3 | W19: Yes | X19: Obesity | Y19: =IF(R48<=5.7,"Normal",IF(R19<=6.5,"Prediabetes","Diabetes")) -> Normal
A20: Id18 | B20: 36.765 | C20: 7.29 | D20: yes | E20: No | F20: Yes | G20: 1 | H20: yes | I20: 1 | J20: =IF(H20="?",INDEX($H$3:$H$2337,MODE($I$3:$I$2337)),H20) -> yes | K20: =IF(G20="No major surgery",0,G20) -> 1 | L20: =PROPER(J20) -> Yes | M20: =PROPER(D20) -> Yes | N20: 36.765 | O20: {=_xlfn.IFS(N20<18.5,"Underweight",N20<25,"Normalweight",N20<30,"Overweight",N20>=30,"Obesity")} -> Obesity | P20: Id18 | Q20: 36.765 | R20: 7.29 | S20: Yes | T20: No | U20: Yes | V20: 1 | W20: Yes | X20: Obesity | Y20: =IF(R49<=5.7,"Normal",IF(R20<=6.5,"Prediabetes","Diabetes")) -> Normal
A21: Id19 | B21: 36.955 | C21: 4.72 | D21: yes | E21: No | F21: No | G21: 1 | H21: yes | I21: 1 | J21: =IF(H21="?",INDEX($H$3:$H$2337,MODE($I$3:$I$2337)),H21) -> yes | K21: =IF(G21="No major surgery",0,G21) -> 1 | L21: =PROPER(J21) -> Yes | M21: =PROPER(D21) -> Yes | N21: 36.955 | O21: {=_xlfn.IFS(N21<18.5,"Underweight",N21<25,"Normalweight",N21<30,"Overweight",N21>=30,"Obesity")} -> Obesity | P21: Id19 | Q21: 36.955 | R21: 4.72 | S21: Yes | T21: No | U21: No | V21: 1 | W21: Yes | X21: Obesity | Y21: =IF(R50<=5.7,"Normal",IF(R21<=6.5,"Prediabetes","Diabetes")) -> Normal
A22: Id20 | B22: 42.9 | C22: 11.41 | D22: No | E22: No | F22: No | G22: No major surgery | H22: yes | I22: 1 | J22: =IF(H22="?",INDEX($H$3:$H$2337,MODE($I$3:$I$2337)),H22) -> yes | K22: =IF(G22="No major surgery",0,G22) -> 0 | L22: =PROPER(J22) -> Yes | M22: =PROPER(D22) -> No | N22: 42.9 | O22: {=_xlfn.IFS(N22<18.5,"Underweight",N22<25,"Normalweight",N22<30,"Overweight",N22>=30,"Obesity")} -> Obesity | P22: Id20 | Q22: 42.9 | R22: 11.41 | S22: No | T22: No | U22: No | V22: 0 | W22: Yes | X22: Obesity | Y22: =IF(R51<=5.7,"Normal",IF(R22<=6.5,"Prediabetes","Diabetes")) -> Normal
A23: Id21 | B23: 36.3 | C23: 11.5 | D23: yes | E23: No | F23: No | G23: 2 | H23: yes | I23: 1 | J23: =IF(H23="?",INDEX($H$3:$H$2337,MODE($I$3:$I$2337)),H23) -> yes | K23: =IF(G23="No major surgery",0,G23) -> 2 | L23: =PROPER(J23) -> Yes | M23: =PROPER(D23) -> Yes | N23: 36.3 | O23: {=_xlfn.IFS(N23<18.5,"Underweight",N23<25,"Normalweight",N23<30,"Overweight",N23>=30,"Obesity")} -> Obesity | P23: Id21 | Q23: 36.3 | R23: 11.5 | S23: Yes | T23: No | U23: No | V23: 2 | W23: Yes | X23: Obesity | Y23: =IF(R52<=5.7,"Normal",IF(R23<=6.5,"Prediabetes","Diabetes")) -> Normal
A24: Id22 | B24: 32.2 | C24: 6.22 | D24: yes | E24: No | F24: No | G24: 2 | H24: yes | I24: 1 | J24: =IF(H24="?",INDEX($H$3:$H$2337,MODE($I$3:$I$2337)),H24) -> yes | K24: =IF(G24="No major surgery",0,G24) -> 2 | L24: =PROPER(J24) -> Yes | M24: =PROPER(D24) -> Yes | N24: 32.2 | O24: {=_xlfn.IFS(N24<18.5,"Underweight",N24<25,"Normalweight",N24<30,"Overweight",N24>=30,"Obesity")} -> Obesity | P24: Id22 | Q24: 32.2 | R24: 6.22 | S24: Yes | T24: No | U24: No | V24: 2 | W24: Yes | X24: Obesity | Y24: =IF(R53<=5.7,"Normal",IF(R24<=6.5,"Prediabetes","Diabetes")) -> Prediabetes
A25: Id23 | B25: 31.3 | C25: 11.38 | D25: No | E25: No | F25: No | G25: 3 | H25: yes | I25: 1 | J25: =IF(H25="?",INDEX($H$3:$H$2337,MODE($I$3:$I$2337)),H25) -> yes | K25: =IF(G25="No major surgery",0,G25) -> 3 | L25: =PROPER(J25) -> Yes | M25: =PROPER(D25) -> No | N25: 31.3 | O25: {=_xlfn.IFS(N25<18.5,"Underweight",N25<25,"Normalweight",N25<30,"Overweight",N25>=30,"Obesity")} -> Obesity | P25: Id23 | Q25: 31.3 | R25: 11.38 | S25: No | T25: No | U25: No | V25: 3 | W25: Yes | X25: Obesity | Y25: =IF(R54<=5.7,"Normal",IF(R25<=6.5,"Prediabetes","Diabetes")) -> Diabetes
A26: Id24 | B26: 41.8 | C26: 7.89 | D26: yes | E26: No | F26: No | G26: 2 | H26: yes | I26: 1 | J26: =IF(H26="?",INDEX($H$3:$H$2337,MODE($I$3:$I$2337)),H26) -> yes | K26: =IF(G26="No major surgery",0,G26) -> 2 | L26: =PROPER(J26) -> Yes | M26: =PROPER(D26) -> Yes | N26: 41.8 | O26: {=_xlfn.IFS(N26<18.5,"Underweight",N26<25,"Normalweight",N26<30,"Overweight",N26>=30,"Obesity")} -> Obesity | P26: Id24 | Q26: 41.8 | R26: 7.89 | S26: Yes | T26: No | U26: No | V26: 2 | W26: Yes | X26: Obesity | Y26: =IF(R55<=5.7,"Normal",IF(R26<=6.5,"Prediabetes","Diabetes")) -> Normal
A27: Id25 | B27: 35.09 | C27: 4.38 | D27: yes | E27: No | F27: No | G27: 2 | H27: yes | I27: 1 | J27: =IF(H27="?",INDEX($H$3:$H$2337,MODE($I$3:$I$2337)),H27) -> yes | K27: =IF(G27="No major surgery",0,G27) -> 2 | L27: =PROPER(J27) -> Yes | M27: =PROPER(D27) -> Yes | N27: 35.09 | O27: {=_xlfn.IFS(N27<18.5,"Underweight",N27<25,"Normalweight",N27<30,"Overweight",N27>=30,"Obesity")} -> Obesity | P27: Id25 | Q27: 35.09 | R27: 4.38 | S27: Yes | T27: No | U27: No | V27: 2 | W27: Yes | X27: Obesity | Y27: =IF(R56<=5.7,"Normal",IF(R27<=6.5,"Prediabetes","Diabetes")) -> Prediabetes
A28: Id26 | B28: 33.88 | C28: 7.01 | D28: No | E28: No | F28: No | G28: 3 | H28: yes | I28: 1 | J28: =IF(H28="?",INDEX($H$3:$H$2337,MODE($I$3:$I$2337)),H28) -> yes | K28: =IF(G28="No major surgery",0,G28) -> 3 | L28: =PROPER(J28) -> Yes | M28: =PROPER(D28) -> No | N28: 33.88 | O28: {=_xlfn.IFS(N28<18.5,"Underweight",N28<25,"Normalweight",N28<30,"Overweight",N28>=30,"Obesity")} -> Obesity | P28: Id26 | Q28: 33.88 | R28: 7.01 | S28: No | T28: No | U28: No | V28: 3 | W28: Yes | X28: Obesity | Y28: =IF(R57<=5.7,"Normal",IF(R28<=6.5,"Prediabetes","Diabetes")) -> Diabetes
A29: Id27 | B29: 30.875 | C29: 11.88 | D29: No | E29: No | F29: No | G29: No major surgery | H29: yes | I29: 1 | J29: =IF(H29="?",INDEX($H$3:$H$2337,MODE($I$3:$I$2337)),H29) -> yes | K29: =IF(G29="No major surgery",0,G29) -> 0 | L29: =PROPER(J29) -> Yes | M29: =PROPER(D29) -> No | N29: 30.875 | O29: {=_xlfn.IFS(N29<18.5,"Underweight",N29<25,"Normalweight",N29<30,"Overweight",N29>=30,"Obesity")} -> Obesity | P29: Id27 | Q29: 30.875 | R29: 11.88 | S29: No | T29: No | U29: No | V29: 0 | W29: Yes | X29: Obesity | Y29: =IF(R58<=5.7,"Normal",IF(R29<=6.5,"Prediabetes","Diabetes")) -> Diabetes
A30: Id28 | B30: 36.86 | C30: 5.19 | D30: yes | E30: No | F30: Yes | G30: 1 | H30: yes | I30: 1 | J30: =IF(H30="?",INDEX($H$3:$H$2337,MODE($I$3:$I$2337)),H30) -> yes | K30: =IF(G30="No major surgery",0,G30) -> 1 | L30: =PROPER(J30) -> Yes | M30: =PROPER(D30) -> Yes | N30: 36.86 | O30: {=_xlfn.IFS(N30<18.5,"Underweight",N30<25,"Normalweight",N30<30,"Overweight",N30>=30,"Obesity")} -> Obesity | P30: Id28 | Q30: 36.86 | R30: 5.19 | S30: Yes | T30: No | U30: Yes | V30: 1 | W30: Yes | X30: Obesity | Y30: =IF(R59<=5.7,"Normal",IF(R30<=6.5,"Prediabetes","Diabetes")) -> Prediabetes
A31: Id29 | B31: 35.86 | C31: 6.74 | D31: yes | E31: No | F31: No | G31: 2 | H31: yes | I31: 1 | J31: =IF(H31="?",INDEX($H$3:$H$2337,MODE($I$3:$I$2337)),H31) -> yes | K31: =IF(G31="No major surgery",0,G31) -> 2 | L31: =PROPER(J31) -> Yes | M31: =PROPER(D31) -> Yes | N31: 35.86 | O31: {=_xlfn.IFS(N31<18.5,"Underweight",N31<25,"Normalweight",N31<30,"Overweight",N31>=30,"Obesity")} -> Obesity | P31: Id29 | Q31: 35.86 | R31: 6.74 | S31: Yes | T31: No | U31: No | V31: 2 | W31: Yes | X31: Obesity | Y31: =IF(R60<=5.7,"Normal",IF(R31<=6.5,"Prediabetes","Diabetes")) -> Diabetes
A32: Id30 | B32: 37.05 | C32: 8.44 | D32: No | E32: No | F32: No | G32: No major surgery | H32: yes | I32: 1 | J32: =IF(H32="?",INDEX($H$3:$H$2337,MODE($I$3:$I$2337)),H32) -> yes | K32: =IF(G32="No major surgery",0,G32) -> 0 | L32: =PROPER(J32) -> Yes | M32: =PROPER(D32) -> No | N32: 37.05 | O32: {=_xlfn.IFS(N32<18.5,"Underweight",N32<25,"Normalweight",N32<30,"Overweight",N32>=30,"Obesity")} -> Obesity | P32: Id30 | Q32: 37.05 | R32: 8.44 | S32: No | T32: No | U32: No | V32: 0 | W32: Yes | X32: Obesity | Y32: =IF(R61<=5.7,"Normal",IF(R32<=6.5,"Prediabetes","Diabetes")) -> Diabetes
A33: Id31 | B33: 43.89 | C33: 8.71 | D33: No | E33: No | F33: No | G33: No major surgery | H33: yes | I33: 1 | J33: =IF(H33="?",INDEX($H$3:$H$2337,MODE($I$3:$I$2337)),H33) -> yes | K33: =IF(G33="No major surgery",0,G33) -> 0 | L33: =PROPER(J33) -> Yes | M33: =PROPER(D33) -> No | N33: 43.89 | O33: {=_xlfn.IFS(N33<18.5,"Underweight",N33<25,"Normalweight",N33<30,"Overweight",N33>=30,"Obesity")} -> Obesity | P33: Id31 | Q33: 43.89 | R33: 8.71 | S33: No | T33: No | U33: No | V33: 0 | W33: Yes | X33: Obesity | Y33: =IF(R62<=5.7,"Normal",IF(R33<=6.5,"Prediabetes","Diabetes")) -> Diabetes
A34: Id32 | B34: 42.35 | C34: 5.08 | D34: yes | E34: No | F34: No | G34: No major surgery | H34: yes | I34: 1 | J34: =IF(H34="?",INDEX($H$3:$H$2337,MODE($I$3:$I$2337)),H34) -> yes | K34: =IF(G34="No major surgery",0,G34) -> 0 | L34: =PROPER(J34) -> Yes | M34: =PROPER(D34) -> Yes | N34: 42.35 | O34: {=_xlfn.IFS(N34<18.5,"Underweight",N34<25,"Normalweight",N34<30,"Overweight",N34>=30,"Obesity")} -> Obesity | P34: Id32 | Q34: 42.35 | R34: 5.08 | S34: Yes | T34: No | U34: No | V34: 0 | W34: Yes | X34: Obesity | Y34: =IF(R63<=5.7,"Normal",IF(R34<=6.5,"Prediabetes","Diabetes")) -> Prediabetes
A35: Id33 | B35: 31.35 | C35: 6.86 | D35: No | E35: No | F35: No | G35: No major surgery | H35: yes | I35: 1 | J35: =IF(H35="?",INDEX($H$3:$H$2337,MODE($I$3:$I$2337)),H35) -> yes | K35: =IF(G35="No major surgery",0,G35) -> 0 | L35: =PROPER(J35) -> Yes | M35: =PROPER(D35) -> No | N35: 31.35 | O35: {=_xlfn.IFS(N35<18.5,"Underweight",N35<25,"Normalweight",N35<30,"Overweight",N35>=30,"Obesity")} -> Obesity | P35: Id33 | Q35: 31.35 | R35: 6.86 | S35: No | T35: No | U35: No | V35: 0 | W35: Yes | X35: Obesity | Y35: =IF(R64<=5.7,"Normal",IF(R35<=6.5,"Prediabetes","Diabetes")) -> Diabetes
A36: Id34 | B36: 47.6 | C36: 5.95 | D36: yes | E36: No | F36: No | G36: No major surgery | H36: yes | I36: 1 | J36: =IF(H36="?",INDEX($H$3:$H$2337,MODE($I$3:$I$2337)),H36) -> yes | K36: =IF(G36="No major surgery",0,G36) -> 0 | L36: =PROPER(J36) -> Yes | M36: =PROPER(D36) -> Yes | N36: 47.6 | O36: {=_xlfn.IFS(N36<18.5,"Underweight",N36<25,"Normalweight",N36<30,"Overweight",N36>=30,"Obesity")} -> Obesity | P36: Id34 | Q36: 47.6 | R36: 5.95 | S36: Yes | T36: No | U36: No | V36: 0 | W36: Yes | X36: Obesity | Y36: =IF(R65<=5.7,"Normal",IF(R36<=6.5,"Prediabetes","Diabetes")) -> Prediabetes
A37: Id35 | B37: 46.2 | C37: 6.09 | D37: No | E37: No | F37: Yes | G37: 1 | H37: yes | I37: 1 | J37: =IF(H37="?",INDEX($H$3:$H$2337,MODE($I$3:$I$2337)),H37) -> yes | K37: =IF(G37="No major surgery",0,G37) -> 1 | L37: =PROPER(J37) -> Yes | M37: =PROPER(D37) -> No | N37: 46.2 | O37: {=_xlfn.IFS(N37<18.5,"Underweight",N37<25,"Normalweight",N37<30,"Overweight",N37>=30,"Obesity")} -> Obesity | P37: Id35 | Q37: 46.2 | R37: 6.09 | S37: No | T37: No | U37: Yes | V37: 1 | W37: Yes | X37: Obesity | Y37: =IF(R66<=5.7,"Normal",IF(R37<=6.5,"Prediabetes","Diabetes")) -> Prediabetes
A38: Id36 | B38: 32.015 | C38: 11.75 | D38: No | E38: No | F38: No | G38: No major surgery | H38: yes | I38: 1 | J38: =IF(H38="?",INDEX($H$3:$H$2337,MODE($I$3:$I$2337)),H38) -> yes | K38: =IF(G38="No major surgery",0,G38) -> 0 | L38: =PROPER(J38) -> Yes | M38: =PROPER(D38) -> No | N38: 32.015 | O38: {=_xlfn.IFS(N38<18.5,"Underweight",N38<25,"Normalweight",N38<30,"Overweight",N38>=30,"Obesity")} -> Obesity | P38: Id36 | Q38: 32.015 | R38: 11.75 | S38: No | T38: No | U38: No | V38: 0 | W38: Yes | X38: Obesity | Y38: =IF(R67<=5.7,"Normal",IF(R38<=6.5,"Prediabetes","Diabetes")) -> Diabetes
A39: Id37 | B39: 40.565 | C39: 7.37 | D39: No | E39: No | F39: No | G39: No major surgery | H39: yes | I39: 1 | J39: =IF(H39="?",INDEX($H$3:$H$2337,MODE($I$3:$I$2337)),H39) -> yes | K39: =IF(G39="No major surgery",0,G39) -> 0 | L39: =PROPER(J39) -> Yes | M39: =PROPER(D39) -> No | N39: 40.565 | O39: {=_xlfn.IFS(N39<18.5,"Underweight",N39<25,"Normalweight",N39<30,"Overweight",N39>=30,"Obesity")} -> Obesity | P39: Id37 | Q39: 40.565 | R39: 7.37 | S39: No | T39: No | U39: No | V39: 0 | W39: Yes | X39: Obesity | Y39: =IF(R68<=5.7,"Normal",IF(R39<=6.5,"Prediabetes","Diabetes")) -> Diabetes
A40: Id38 | B40: 32.45 | C40: 11.91 | D40: No | E40: No | F40: No | G40: No major surgery | H40: yes | I40: 1 | J40: =IF(H40="?",INDEX($H$3:$H$2337,MODE($I$3:$I$2337)),H40) -> yes | K40: =IF(G40="No major surgery",0,G40) -> 0 | L40: =PROPER(J40) -> Yes | M40: =PROPER(D40) -> No | N40: 32.45 | O40: {=_xlfn.IFS(N40<18.5,"Underweight",N40<25,"Normalweight",N40<30,"Overweight",N40>=30,"Obesity")} -> Obesity | P40: Id38 | Q40: 32.45 | R40: 11.91 | S40: No | T40: No | U40: No | V40: 0 | W40: Yes | X40: Obesity | Y40: =IF(R69<=5.7,"Normal",IF(R40<=6.5,"Prediabetes","Diabetes")) -> Diabetes
...

Sheet Hospitalisation Details Cleanin
J1: IF(B3="?",ROUND(AVERAGE($B$3:$B$2345),0),B3) | K1: IF(C3="?","Sep",C3) | L1: MATCH($G$4:$G$2346,$G$4:$G$2346,0) | M1: IF(G4="?",INDEX($G$4:$G$2346,MODE($L$4:$L$2346)),G4) | N1: MATCH($H$4:$H$2346,$H$4:$H$2346,0) | O1: IF(H4="?",INDEX($H$4:$H$2346,MODE($N$4:$N$2346)),H4) | P1: IF(I4="?","Unknown",I4) | Q1: CONCATENATE(D4,"-",K4,"-",J4) | R1: Text to Cloumn
L2: =MODE($L$4:$L$2346) -> 1 | M2: =INDEX($G$4:$G$2346,L2) -> tier - 2 | N2: =MODE($N$4:$N$2346) -> 9 | O2: =INDEX($H$4:$H$2346,N2) -> tier - 2 | S2: 45085
A3: Customer ID | B3: year | C3: month | D3: date | E3: children | F3: charges | G3: Hospital tier | H3: City tier | I3: State ID | J3: year | K3: month | L3: Hospital tier Encoding | M3: Hospital tier impute | N3: City tier Encoding | O3: City tier Impute | P3: State ID | Q3: Date Of Birth | R3: Date Of Birth | S3: Customer Age | T3: charges | U3: Customer ID | V3: Date Of Birth | W3: children | X3: charges | Y3: Hospital tier | Z3: City tier | AA3: State ID | AB3: Customer Age
A4: Id2335 | B4: 1992 | C4: Jul | D4: 9 | E4: 0 | F4: 563.84 | G4: tier - 2 | H4: tier - 3 | I4: R1013 | J4: 1992 | K4: Jul | L4: =MATCH($G$4:$G$2346,$G$4:$G$2346,0) -> 1 | M4: =IF(G4="?",INDEX($G$4:$G$2346,MODE($L$4:$L$2346)),G4) -> tier - 2 | N4: =MATCH($H$4:$H$2346,$H$4:$H$2346,0) -> 1 | O4: =IF(H4="?",INDEX($H$4:$H$2346,MODE($N$4:$N$2346)),H4) -> tier - 3 | P4: =IF(I4="?","Unknown",I4) -> R1013 | Q4: =CONCATENATE(D4,"-",K4,"-",J4) -> 9-Jul-1992 | R4: 33794 | S4: =ROUND((($S$2-R4)/365),0) -> 31 | T4: 563.84 | U4: Id2335 | V4: 33794 | W4: 0 | X4: 563.84 | Y4: tier - 2 | Z4: tier - 3 | AA4: R1013 | AB4: 31
A5: Id2334 | B5: 1992 | C5: Nov | D5: 30 | E5: 0 | F5: 570.62 | G5: tier - 2 | H5: tier - 1 | I5: R1013 | J5: 1992 | K5: Nov | L5: =MATCH($G$4:$G$2346,$G$4:$G$2346,0) -> 1 | M5: =IF(G5="?",INDEX($G$4:$G$2346,MODE($L$4:$L$2346)),G5) -> tier - 2 | N5: =MATCH($H$4:$H$2346,$H$4:$H$2346,0) -> 2 | O5: =IF(H5="?",INDEX($H$4:$H$2346,MODE($N$4:$N$2346)),H5) -> tier - 1 | P5: =IF(I5="?","Unknown",I5) -> R1013 | Q5: =CONCATENATE(D5,"-",K5,"-",J5) -> 30-Nov-1992 | R5: 33938 | S5: =ROUND((($S$2-R5)/365),0) -> 31 | T5: 570.62 | U5: Id2334 | V5: 33938 | W5: 0 | X5: 570.62 | Y5: tier - 2 | Z5: tier - 1 | AA5: R1013 | AB5: 31
A6: Id2333 | B6: 1993 | C6: Jun | D6: 30 | E6: 0 | F6: 600 | G6: tier - 2 | H6: tier - 1 | I6: R1013 | J6: 1993 | K6: Jun | L6: =MATCH($G$4:$G$2346,$G$4:$G$2346,0) -> 1 | M6: =IF(G6="?",INDEX($G$4:$G$2346,MODE($L$4:$L$2346)),G6) -> tier - 2 | N6: =MATCH($H$4:$H$2346,$H$4:$H$2346,0) -> 2 | O6: =IF(H6="?",INDEX($H$4:$H$2346,MODE($N$4:$N$2346)),H6) -> tier - 1 | P6: =IF(I6="?","Unknown",I6) -> R1013 | Q6: =CONCATENATE(D6,"-",K6,"-",J6) -> 30-Jun-1993 | R6: 34150 | S6: =ROUND((($S$2-R6)/365),0) -> 30 | T6: 600 | U6: Id2333 | V6: 34150 | W6: 0 | X6: 600 | Y6: tier - 2 | Z6: tier - 1 | AA6: R1013 | AB6: 30
A7: Id2332 | B7: 1992 | C7: Sep | D7: 13 | E7: 0 | F7: 604.54 | G7: tier - 3 | H7: tier - 3 | I7: R1013 | J7: 1992 | K7: Sep | L7: =MATCH($G$4:$G$2346,$G$4:$G$2346,0) -> 4 | M7: =IF(G7="?",INDEX($G$4:$G$2346,MODE($L$4:$L$2346)),G7) -> tier - 3 | N7: =MATCH($H$4:$H$2346,$H$4:$H$2346,0) -> 1 | O7: =IF(H7="?",INDEX($H$4:$H$2346,MODE($N$4:$N$2346)),H7) -> tier - 3 | P7: =IF(I7="?","Unknown",I7) -> R1013 | Q7: =CONCATENATE(D7,"-",K7,"-",J7) -> 13-Sep-1992 | R7: 33860 | S7: =ROUND((($S$2-R7)/365),0) -> 31 | T7: 604.54 | U7: Id2332 | V7: 33860 | W7: 0 | X7: 604.54 | Y7: tier - 3 | Z7: tier - 3 | AA7: R1013 | AB7: 31
A8: Id2331 | B8: 1998 | C8: Jul | D8: 27 | E8: 0 | F8: 637.26 | G8: tier - 3 | H8: tier - 3 | I8: R1013 | J8: 1998 | K8: Jul | L8: =MATCH($G$4:$G$2346,$G$4:$G$2346,0) -> 4 | M8: =IF(G8="?",INDEX($G$4:$G$2346,MODE($L$4:$L$2346)),G8) -> tier - 3 | N8: =MATCH($H$4:$H$2346,$H$4:$H$2346,0) -> 1 | O8: =IF(H8="?",INDEX($H$4:$H$2346,MODE($N$4:$N$2346)),H8) -> tier - 3 | P8: =IF(I8="?","Unknown",I8) -> R1013 | Q8: =CONCATENATE(D8,"-",K8,"-",J8) -> 27-Jul-1998 | R8: 36003 | S8: =ROUND((($S$2-R8)/365),0) -> 25 | T8: 637.26 | U8: Id2331 | V8: 36003 | W8: 0 | X8: 637.26 | Y8: tier - 3 | Z8: tier - 3 | AA8: R1013 | AB8: 25
A9: Id2330 | B9: 2001 | C9: Nov | D9: 20 | E9: 0 | F9: 646.14 | G9: tier - 3 | H9: tier - 3 | I9: R1012 | J9: 2001 | K9: Nov | L9: =MATCH($G$4:$G$2346,$G$4:$G$2346,0) -> 4 | M9: =IF(G9="?",INDEX($G$4:$G$2346,MODE($L$4:$L$2346)),G9) -> tier - 3 | N9: =MATCH($H$4:$H$2346,$H$4:$H$2346,0) -> 1 | O9: =IF(H9="?",INDEX($H$4:$H$2346,MODE($N$4:$N$2346)),H9) -> tier - 3 | P9: =IF(I9="?","Unknown",I9) -> R1012 | Q9: =CONCATENATE(D9,"-",K9,"-",J9) -> 20-Nov-2001 | R9: 37215 | S9: =ROUND((($S$2-R9)/365),0) -> 22 | T9: 646.14 | U9: Id2330 | V9: 37215 | W9: 0 | X9: 646.14 | Y9: tier - 3 | Z9: tier - 3 | AA9: R1012 | AB9: 22
A10: Id2329 | B10: 1993 | C10: Jun | D10: 1 | E10: 0 | F10: 650 | G10: tier - 3 | H10: tier - 3 | I10: R1013 | J10: 1993 | K10: Jun | L10: =MATCH($G$4:$G$2346,$G$4:$G$2346,0) -> 4 | M10: =IF(G10="?",INDEX($G$4:$G$2346,MODE($L$4:$L$2346)),G10) -> tier - 3 | N10: =MATCH($H$4:$H$2346,$H$4:$H$2346,0) -> 1 | O10: =IF(H10="?",INDEX($H$4:$H$2346,MODE($N$4:$N$2346)),H10) -> tier - 3 | P10: =IF(I10="?","Unknown",I10) -> R1013 | Q10: =CONCATENATE(D10,"-",K10,"-",J10) -> 1-Jun-1993 | R10: 34121 | S10: =ROUND((($S$2-R10)/365),0) -> 30 | T10: 650 | U10: Id2329 | V10: 34121 | W10: 0 | X10: 650 | Y10: tier - 3 | Z10: tier - 3 | AA10: R1013 | AB10: 30
A11: Id2328 | B11: 1995 | C11: Jul | D11: 4 | E11: 0 | F11: 650 | G11: tier - 3 | H11: tier - 3 | I11: R1013 | J11: 1995 | K11: Jul | L11: =MATCH($G$4:$G$2346,$G$4:$G$2346,0) -> 4 | M11: =IF(G11="?",INDEX($G$4:$G$2346,MODE($L$4:$L$2346)),G11) -> tier - 3 | N11: =MATCH($H$4:$H$2346,$H$4:$H$2346,0) -> 1 | O11: =IF(H11="?",INDEX($H$4:$H$2346,MODE($N$4:$N$2346)),H11) -> tier - 3 | P11: =IF(I11="?","Unknown",I11) -> R1013 | Q11: =CONCATENATE(D11,"-",K11,"-",J11) -> 4-Jul-1995 | R11: 34884 | S11: =ROUND((($S$2-R11)/365),0) -> 28 | T11: 650 | U11: Id2328 | V11: 34884 | W11: 0 | X11: 650 | Y11: tier - 3 | Z11: tier - 3 | AA11: R1013 | AB11: 28
A12: Id2327 | B12: 2002 | C12: Nov | D12: 29 | E12: 0 | F12: 668 | G12: tier - 3 | H12: tier - 2 | I12: R1012 | J12: 2002 | K12: Nov | L12: =MATCH($G$4:$G$2346,$G$4:$G$2346,0) -> 4 | M12: =IF(G12="?",INDEX($G$4:$G$2346,MODE($L$4:$L$2346)),G12) -> tier - 3 | N12: =MATCH($H$4:$H$2346,$H$4:$H$2346,0) -> 9 | O12: =IF(H12="?",INDEX($H$4:$H$2346,MODE($N$4:$N$2346)),H12) -> tier - 2 | P12: =IF(I12="?","Unknown",I12) -> R1012 | Q12: =CONCATENATE(D12,"-",K12,"-",J12) -> 29-Nov-2002 | R12: 37589 | S12: =ROUND((($S$2-R12)/365),0) -> 21 | T12: 668 | U12: Id2327 | V12: 37589 | W12: 0 | X12: 668 | Y12: tier - 3 | Z12: tier - 2 | AA12: R1012 | AB12: 21
A13: Id2326 | B13: 1997 | C13: Nov | D13: 9 | E13: 0 | F13: 670 | G13: tier - 3 | H13: tier - 3 | I13: R1013 | J13: 1997 | K13: Nov | L13: =MATCH($G$4:$G$2346,$G$4:$G$2346,0) -> 4 | M13: =IF(G13="?",INDEX($G$4:$G$2346,MODE($L$4:$L$2346)),G13) -> tier - 3 | N13: =MATCH($H$4:$H$2346,$H$4:$H$2346,0) -> 1 | O13: =IF(H13="?",INDEX($H$4:$H$2346,MODE($N$4:$N$2346)),H13) -> tier - 3 | P13: =IF(I13="?","Unknown",I13) -> R1013 | Q13: =CONCATENATE(D13,"-",K13,"-",J13) -> 9-Nov-1997 | R13: 35743 | S13: =ROUND((($S$2-R13)/365),0) -> 26 | T13: 670 | U13: Id2326 | V13: 35743 | W13: 0 | X13: 670 | Y13: tier - 3 | Z13: tier - 3 | AA13: R1013 | AB13: 26
A14: Id2325 | B14: 2001 | C14: Sep | D14: 12 | E14: 0 | F14: 687.54 | G14: tier - 3 | H14: tier - 2 | I14: R1013 | J14: 2001 | K14: Sep | L14: =MATCH($G$4:$G$2346,$G$4:$G$2346,0) -> 4 | M14: =IF(G14="?",INDEX($G$4:$G$2346,MODE($L$4:$L$2346)),G14) -> tier - 3 | N14: =MATCH($H$4:$H$2346,$H$4:$H$2346,0) -> 9 | O14: =IF(H14="?",INDEX($H$4:$H$2346,MODE($N$4:$N$2346)),H14) -> tier - 2 | P14: =IF(I14="?","Unknown",I14) -> R1013 | Q14: =CONCATENATE(D14,"-",K14,"-",J14) -> 12-Sep-2001 | R14: 37146 | S14: =ROUND((($S$2-R14)/365),0) -> 22 | T14: 687.54 | U14: Id2325 | V14: 37146 | W14: 0 | X14: 687.54 | Y14: tier - 3 | Z14: tier - 2 | AA14: R1013 | AB14: 22
A15: Id2324 | B15: 1999 | C15: Dec | D15: 26 | E15: 0 | F15: 700 | G15: ? | H15: tier - 3 | I15: R1013 | J15: 1999 | K15: Dec | L15: =MATCH($G$4:$G$2346,$G$4:$G$2346,0) -> 12 | M15: =IF(G15="?",INDEX($G$4:$G$2346,MODE($L$4:$L$2346)),G15) -> tier - 2 | N15: =MATCH($H$4:$H$2346,$H$4:$H$2346,0) -> 1 | O15: =IF(H15="?",INDEX($H$4:$H$2346,MODE($N$4:$N$2346)),H15) -> tier - 3 | P15: =IF(I15="?","Unknown",I15) -> R1013 | Q15: =CONCATENATE(D15,"-",K15,"-",J15) -> 26-Dec-1999 | R15: 36520 | S15: =ROUND((($S$2-R15)/365),0) -> 23 | T15: 700 | U15: Id2324 | V15: 36520 | W15: 0 | X15: 700 | Y15: tier - 2 | Z15: tier - 3 | AA15: R1013 | AB15: 23
... A1052: Id1290 | B1052: 1977 | C1052: Jul | D1052: 26 | E1052: 2 | F1052: 8527.53 | G1052: tier - 2 | H1052: tier - 2 | I1052: R1013 | J1052: 1977 | K1052: Jul | L1052: =MATCH($G$4:$G$2346,$G$4:$G$2346,0) -> 1 | M1052: =IF(G1052="?",INDEX($G$4:$G$2346,MODE($L$4:$L$2346)),G1052) -> tier - 2 | N1052: =MATCH($H$4:$H$2346,$H$4:$H$2346,0) -> 9 | O1052: =IF(H1052="?",INDEX($H$4:$H$2346,MODE($N$4:$N$2346)),H1052) -> tier - 2 | P1052: =IF(I1052="?","Unknown",I1052) -> R1013 | Q1052: =CONCATENATE(D1052,"-",K1052,"-",J1052) -> 26-Jul-1977 | R1052: 28332 | S1052: =ROUND((($S$2-R1052)/365),0) -> 46 | T1052: 8527.53 | U1052: Id1290 | V1052: 28332 | W1052: 2 | X1052: 8527.53 | Y1052: tier - 2 | Z1052: tier - 2 | AA1052: R1013 | AB1052: 46
A1053: Id1289 | B1053: ? | C1053: Jul | D1053: 24 | E1053: 0 | F1053: 8534.67 | G1053: tier - 2 | H1053: tier - 3 | I1053: R1024 | J1053: 1983 | K1053: Jul | L1053: =MATCH($G$4:$G$2346,$G$4:$G$2346,0) -> 1 | M1053: =IF(G1053="?",INDEX($G$4:$G$2346,MODE($L$4:$L$2346)),G1053) -> tier - 2 | N1053: =MATCH($H$4:$H$2346,$H$4:$H$2346,0) -> 1 | O1053: =IF(H1053="?",INDEX($H$4:$H$2346,MODE($N$4:$N$2346)),H1053) -> tier - 3 | P1053: =IF(I1053="?","Unknown",I1053) -> R1024 | Q1053: =CONCATENATE(D1053,"-",K1053,"-",J1053) -> 24-Jul-1983 | R1053: 30521 | S1053: =ROUND((($S$2-R1053)/365),0) -> 40 | T1053: 8534.67 | U1053: Id1289 | V1053: 30521 | W1053: 0 | X1053: 8534.67 | Y1053: tier - 2 | Z1053: tier - 3 | AA1053: R1024 | AB1053: 40
A1054: Id1288 | B1054: 1981 | C1054: Dec | D1054: 27 | E1054: 3 | F1054: 8538.29 | G1054: tier - 2 | H1054: tier - 3 | I1054: R1024 | J1054: 1981 | K1054: Dec | L1054: =MATCH($G$4:$G$2346,$G$4:$G$2346,0) -> 1 | M1054: =IF(G1054="?",INDEX($G$4:$G$2346,MODE($L$4:$L$2346)),G1054) -> tier - 2 | N1054: =MATCH($H$4:$H$2346,$H$4:$H$2346,0) -> 1 | O1054: =IF(H1054="?",INDEX($H$4:$H$2346,MODE($N$4:$N$2346)),H1054) -> tier - 3 | P1054: =IF(I1054="?","Unknown",I1054) -> R1024 | Q1054: =CONCATENATE(D1054,"-",K1054,"-",J1054) -> 27-Dec-1981 | R1054: 29947 | S1054: =ROUND((($S$2-R1054)/365),0) -> 41 | T1054: 8538.29 | U1054: Id1288 | V1054: 29947 | W1054: 3 | X1054: 8538.29 | Y1054: tier - 2 | Z1054: tier - 3 | AA1054: R1024 | AB1054: 41
A1055: Id1287 | B1055: 1975 | C1055: Nov | D1055: 6 | E1055: 1 | F1055: 8539.67 | G1055: tier - 2 | H1055: tier - 3 | I1055: R1011 | J1055: 1975 | K1055: Nov | L1055: =MATCH($G$4:$G$2346,$G$4:$G$2346,0) -> 1 | M1055: =IF(G1055="?",INDEX($G$4:$G$2346,MODE($L$4:$L$2346)),G1055) -> tier - 2 | N1055: =MATCH($H$4:$H$2346,$H$4:$H$2346,0) -> 1 | O1055: =IF(H1055="?",INDEX($H$4:$H$2346,MODE($N$4:$N$2346)),H1055) -> tier - 3 | P1055: =IF(I1055="?","Unknown",I1055) -> R1011 | Q1055: =CONCATENATE(D1055,"-",K1055,"-",J1055) -> 6-Nov-1975 | R1055: 27704 | S1055: =ROUND((($S$2-R1055)/365),0) -> 48 | T1055: 8539.67 | U1055: Id1287 | V1055: 27704 | W1055: 1 | X1055: 8539.67 | Y1055: tier - 2 | Z1055: tier - 3 | AA1055: R1011 | AB1055: 48
A1056: Id1286 | B1056: ? | C1056: Dec | D1056: 12 | E1056: 1 | F1056: 8547.69 | G1056: tier - 2 | H1056: tier - 1 | I1056: R1013 | J1056: 1983 | K1056: Dec | L1056: =MATCH($G$4:$G$2346,$G$4:$G$2346,0) -> 1 | M1056: =IF(G1056="?",INDEX($G$4:$G$2346,MODE($L$4:$L$2346)),G1056) -> tier - 2 | N1056: =MATCH($H$4:$H$2346,$H$4:$H$2346,0) -> 2 | O1056: =IF(H1056="?",INDEX($H$4:$H$2346,MODE($N$4:$N$2346)),H1056) -> tier - 1 | P1056: =IF(I1056="?","Unknown",I1056) -> R1013 | Q1056: =CONCATENATE(D1056,"-",K1056,"-",J1056) -> 12-Dec-1983 | R1056: 30662 | S1056: =ROUND((($S$2-R1056)/365),0) -> 40 | T1056: 8547.69 | U1056: Id1286 | V1056: 30662 | W1056: 1 | X1056: 8547.69 | Y1056: tier - 2 | Z1056: tier - 1 | AA1056: R1013 | AB1056: 40
A1057: Id1285 | B1057: 1975 | C1057: Aug | D1057: 6 | E1057: 1 | F1057: 8551.35 | G1057: tier - 2 | H1057: tier - 2 | I1057: R1011 | J1057: 1975 | K1057: Aug | L1057: =MATCH($G$4:$G$2346,$G$4:$G$2346,0) -> 1 | M1057: =IF(G1057="?",INDEX($G$4:$G$2346,MODE($L$4:$L$2346)),G1057) -> tier - 2 | N1057: =MATCH($H$4:$H$2346,$H$4:$H$2346,0) -> 9 | O1057: =IF(H1057="?",INDEX($H$4:$H$2346,MODE($N$4:$N$2346)),H1057) -> tier - 2 | P1057: =IF(I1057="?","Unknown",I1057) -> R1011 | Q1057: =CONCATENATE(D1057,"-",K1057,"-",J1057) -> 6-Aug-1975 | R1057: 27612 | S1057: =ROUND((($S$2-R1057)/365),0) -> 48 | T1057: 8551.35 | U1057: Id1285 | V1057: 27612 | W1057: 1 | X1057: 8551.35 | Y1057: tier - 2 | Z1057: tier - 2 | AA1057: R1011 | AB1057: 48
A1058: Id1284 | B1058: 1975 | C1058: Aug | D1058: 21 | E1058: 1 | F1058: 8556.91 | G1058: tier - 2 | H1058: tier - 1 | I1058: R1011 | J1058: 1975 | K1058: Aug | L1058: =MATCH($G$4:$G$2346,$G$4:$G$2346,0) -> 1 | M1058: =IF(G1058="?",INDEX($G$4:$G$2346,MODE($L$4:$L$2346)),G1058) -> tier - 2 | N1058: =MATCH($H$4:$H$2346,$H$4:$H$2346,0) -> 2 | O1058: =IF(H1058="?",INDEX($H$4:$H$2346,MODE($N$4:$N$2346)),H1058) -> tier - 1 | P1058: =IF(I1058="?","Unknown",I1058) -> R1011 | Q1058: =CONCATENATE(D1058,"-",K1058,"-",J1058) -> 21-Aug-1975 | R1058: 27627 | S1058: =ROUND((($S$2-R1058)/365),0) -> 48 | T1058: 8556.91 | U1058: Id1284 | V1058: 27627 | W1058: 1 | X1058: 8556.91 | Y1058: tier - 2 | Z1058: tier - 1 | AA1058: R1011 | AB1058: 48
A1059: Id1283 | B1059: 1988 | C1059: Sep | D1059: 21 | E1059: 3 | F1059: 8567.25 | G1059: tier - 2 | H1059: tier - 1 | I1059: R1012 | J1059: 1988 | K1059: Sep | L1059: =MATCH($G$4:$G$2346,$G$4:$G$2346,0) -> 1 | M1059: =IF(G1059="?",INDEX($G$4:$G$2346,MODE($L$4:$L$2346)),G1059) -> tier - 2 | N1059: =MATCH($H$4:$H$2346,$H$4:$H$2346,0) -> 2 | O1059: =IF(H1059="?",INDEX($H$4:$H$2346,MODE($N$4:$N$2346)),H1059) -> tier - 1 | P1059: =IF(I1059="?","Unknown",I1059) -> R1012 | Q1059: =CONCATENATE(D1059,"-",K1059,"-",J1059) -> 21-Sep-1988 | R1059: 32407 | S1059: =ROUND((($S$2-R1059)/365),0) -> 35 | T1059: 8567.25 | U1059: Id1283 | V1059: 32407 | W1059: 3 | X1059: 8567.25 | Y1059: tier - 2 | Z1059: tier - 1 | AA1059: R1012 | AB1059: 35
A1060: Id1282 | B1060: 1975 | C1060: Sep | D1060: 26 | E1060: 1 | F1060: 8569.86 | G1060: tier - 2 | H1060: tier - 3 | I1060: R1013 | J1060: 1975 | K1060: Sep | L1060: =MATCH($G$4:$G$2346,$G$4:$G$2346,0) -> 1 | M1060: =IF(G1060="?",INDEX($G$4:$G$2346,MODE($L$4:$L$2346)),G1060) -> tier - 2 | N1060: =MATCH($H$4:$H$2346,$H$4:$H$2346,0) -> 1 | O1060: =IF(H1060="?",INDEX($H$4:$H$2346,MODE($N$4:$N$2346)),H1060) -> tier - 3 | P1060: =IF(I1060="?","Unknown",I1060) -> R1013 | Q1060: =CONCATENATE(D1060,"-",K1060,"-",J1060) -> 26-Sep-1975 | R1060: 27663 | S1060: =ROUND((($S$2-R1060)/365),0) -> 48 | T1060: 8569.86 | U1060: Id1282 | V1060: 27663 | W1060: 1 | X1060: 8569.86 | Y1060: tier - 2 | Z1060: tier - 3 | AA1060: R1013 | AB1060: 48
A1061: Id1281 | B1061: 1982 | C1061: Dec | D1061: 6 | E1061: 3 | F1061: 8572.04 | G1061: tier - 2 | H1061: tier - 2 | I1061: R1021 | J1061: 1982 | K1061: Dec | L1061: =MATCH($G$4:$G$2346,$G$4:$G$2346,0) -> 1 | M1061: =IF(G1061="?",INDEX($G$4:$G$2346,MODE($L$4:$L$2346)),G1061) -> tier - 2 | N1061: =MATCH($H$4:$H$2346,$H$4:$H$2346,0) -> 9 | O1061: =IF(H1061="?",INDEX($H$4:$H$2346,MODE($N$4:$N$2346)),H1061) -> tier - 2 | P1061: =IF(I1061="?","Unknown",I1061) -> R1021 | Q1061: =CONCATENATE(D1061,"-",K1061,"-",J1061) -> 6-Dec-1982 | R1061: 30291 | S1061: =ROUND((($S$2-R1061)/365),0) -> 41 | T1061: 8572.04 | U1061: Id1281 | V1061: 30291 | W1061: 3 | X1061: 8572.04 | Y1061: tier - 2 | Z1061: tier - 2 | AA1061: R1021 | AB1061: 41
A1062: Id1280 | B1062: 1987 | C1062: Nov | D1062: 11 | E1062: 3 | F1062: 8573.3 | G1062: tier - 2 | H1062: tier - 2 | I1062: R1021 | J1062: 1987 | K1062: Nov | L1062: =MATCH($G$4:$G$2346,$G$4:$G$2346,0) -> 1 | M1062: =IF(G1062="?",INDEX($G$4:$G$2346,MODE($L$4:$L$2346)),G1062) -> tier - 2 | N1062: =MATCH($H$4:$H$2346,$H$4:$H$2346,0) -> 9 | O1062: =IF(H1062="?",INDEX($H$4:$H$2346,MODE($N$4:$N$2346)),H1062) -> tier - 2 | P1062: =IF(I1062="?","Unknown",I1062) -> R1021 | Q1062: =CONCATENATE(D1062,"-",K1062,"-",J1062) -> 11-Nov-1987 | R1062: 32092 | S1062: =ROUND((($S$2-R1062)/365),0) -> 36 | T1062: 8573.3 | U1062: Id1280 | V1062: 32092 | W1062: 3 | X1062: 8573.3 | Y1062: tier - 2 | Z1062: tier - 2 | AA1062: R1021 | AB1062: 36
A1063: Id1279 | B1063: 1983 | C1063: Dec | D1063: 30 | E1063: 5 | F1063: 8582.3 | G1063: tier - 2 | H1063: tier - 1 | I1063: R1013 | J1063: 1983 | K1063: Dec | L1063: =MATCH($G$4:$G$2346,$G$4:$G$2346,0) -> 1 | M1063: =IF(G1063="?",INDEX($G$4:$G$2346,MODE($L$4:$L$2346)),G1063) -> tier - 2 | N1063: =MATCH($H$4:$H$2346,$H$4:$H$2346,0) -> 2 | O1063: =IF(H1063="?",INDEX($H$4:$H$2346,MODE($N$4:$N$2346)),H1063) -> tier - 1 | P1063: =IF(I1063="?","Unknown",I1063) -> R1013 | Q1063: =CONCATENATE(D1063,"-",K1063,"-",J1063) -> 30-Dec-1983 | R1063: 30680 | S1063: =ROUND((($S$2-R1063)/365),0) -> 39 | T1063: 8582.3 | U1063: Id1279 | V1063: 30680 | W1063: 5 | X1063: 8582.3 | Y1063: tier - 2 | Z1063: tier - 1 | AA1063: R1013 | AB1063: 39
A1064: Id1278 | B1064: 1983 | C1064: Jul | D1064: 25 | E1064: 5 | F1064: 8596.83 | G1064: tier - 2 | H1064: tier - 3 | I1064: R1013 | J1064: 1983 | K1064: Jul | L1064: =MATCH($G$4:$G$2346,$G$4:$G$2346,0) -> 1 | M1064: =IF(G1064="?",INDEX($G$4:$G$2346,MODE($L$4:$L$2346)),G1064) -> tier - 2 | N1064: =MATCH($H$4:$H$2346,$H$4:$H$2346,0) -> 1 | O1064: =IF(H1064="?",INDEX($H$4:$H$2346,MODE($N$4:$N$2346)),H1064) -> tier - 3 | P1064: =IF(I1064="?","Unknown",I1064) -> R1013 | Q1064: =CONCATENATE(D1064,"-",K1064,"-",J1064) -> 25-Jul-1983 | R1064: 30522 | S1064: =ROUND((($S$2-R1064)/365),0) -> 40 | T1064: 8596.83 | U1064: Id1278 | V1064: 30522 | W1064: 5 | X1064: 8596.83 | Y1064: tier - 2 | Z1064: tier - 3 | AA1064: R1013 | AB1064: 40
A1065: Id1277 | B1065: 1973 | C1065: Jul | D1065: 11 | E1065: 0 | F1065: 8601.33 | G1065: tier - 2 | H1065: tier - 1 | I1065: R1013 | J1065: 1973 | K1065: Jul | L1065: =MATCH($G$4:$G$2346,$G$4:$G$2346,0) -> 1 | M1065: =IF(G1065="?",INDEX($G$4:$G$2346,MODE($L$4:$L$2346)),G1065) -> tier - 2 | N1065: =MATCH($H$4:$H$2346,$H$4:$H$2346,0) -> 2 | O1065: =IF(H1065="?",INDEX($H$4:$H$2346,MODE($N$4:$N$2346)),H1065) -> tier - 1 | P1065: =IF(I1065="?","Unknown",I1065) -> R1013 | Q1065: =CONCATENATE(D1065,"-",K1065,"-",J1065) -> 11-Jul-1973 | R1065: 26856 | S1065: =ROUND((($S$2-R1065)/365),0) -> 50 | T1065: 8601.33 | U1065: Id1277 | V1065: 26856 | W1065: 0 | X1065: 8601.33 | Y1065: tier - 2 | Z1065: tier - 1 | AA1065: R1013 | AB1065: 50
A1066: Id1276 | B1066: 1977 | C1066: Sep | D1066: 24 | E1066: 2 | F1066: 8603.82 | G1066: tier - 2 | H1066: tier - 1 | I1066: R1019 | J1066: 1977 | K1066: Sep | L1066: =MATCH($G$4:$G$2346,$G$4:$G$2346,0) -> 1 | M1066: =IF(G1066="?",INDEX($G$4:$G$2346,MODE($L$4:$L$2346)),G1066) -> tier - 2 | N1066: =MATCH($H$4:$H$2346,$H$4:$H$2346,0) -> 2 | O1066: =IF(H1066="?",INDEX($H$4:$H$2346,MODE($N$4:$N$2346)),H1066) -> tier - 1 | P1066: =IF(I1066="?","Unknown",I1066) -> R1019 | Q1066: =CONCATENATE(D1066,"-",K1066,"-",J1066) -> 24-Sep-1977 | R1066: 28392 | S1066: =ROUND((($S$2-R1066)/365),0) -> 46 | T1066: 8603.82 | U1066: Id1276 | V1066: 28392 | W1066: 2 | X1066: 8603.82 | Y1066: tier - 2 | Z1066: tier - 1 | AA1066: R1019 | AB1066: 46
A1067: Id1275 | B1067: 1977 | C1067: Nov | D1067: 12 | E1067: 2 | F1067: 8604.48 | G1067: tier - 3 | H1067: tier - 2 | I1067: R1016 | J1067: 1977 | K1067: Nov | L1067: =MATCH($G$4:$G$2346,$G$4:$G$2346,0) -> 4 | M1067: =IF(G1067="?",INDEX($G$4:$G$2346,MODE($L$4:$L$2346)),G1067) -> tier - 3 | N1067: =MATCH($H$4:$H$2346,$H$4:$H$2346,0) -> 9 | O1067: =IF(H1067="?",INDEX($H$4:$H$2346,MODE($N$4:$N$2346)),H1067) -> tier - 2 | P1067: =IF(I1067="?","Unknown",I1067) -> R1016 | Q1067: =CONCATENATE(D1067,"-",K1067,"-",J1067) -> 12-Nov-1977 | R1067: 28441 | S1067: =ROUND((($S$2-R1067)/365),0) -> 46 | T1067: 8604.48 | U1067: Id1275 | V1067: 28441 | W1067: 2 | X1067: 8604.48 | Y1067: tier - 3 | Z1067: tier - 2 | AA1067: R1016 | AB1067: 46
A1068: Id1274 | B1068: 1977 | C1068: Oct | D1068: 15 | E1068: 3 | F1068: 8605.36 | G1068: tier - 2 | H1068: tier - 2 | I1068: R1013 | J1068: 1977 | K1068: Oct | L1068: =MATCH($G$4:$G$2346,$G$4:$G$2346,0) -> 1 | M1068: =IF(G1068="?",INDEX($G$4:$G$2346,MODE($L$4:$L$2346)),G1068) -> tier - 2 | N1068: =MATCH($H$4:$H$2346,$H$4:$H$2346,0) -> 9 | O1068: =IF(H1068="?",INDEX($H$4:$H$2346,MODE($N$4:$N$2346)),H1068) -> tier - 2 | P1068: =IF(I1068="?","Unknown",I1068) -> R1013 | Q1068: =CONCATENATE(D1068,"-",K1068,"-",J1068) -> 15-Oct-1977 | R1068: 28413 | S1068: =ROUND((($S$2-R1068)/365),0) -> 46 | T1068: 8605.36 | U1068: Id1274 | V1068: 28413 | W1068: 3 | X1068: 8605.36 | Y1068: tier - 2 | Z1068: tier - 2 | AA1068: R1013 | AB1068: 46
... A2346: Id1 | B2346: 1968 | C2346: Oct | D2346: 12 | E2346: 0 | F2346: 63770.43 | G2346: tier - 1 | H2346: tier - 3 | I2346: R1013 | J2346: 1968 | K2346: Oct | L2346: =MATCH($G$4:$G$2346,$G$4:$G$2346,0) -> 240 | M2346: =IF(G2346="?",INDEX($G$4:$G$2346,MODE($L$4:$L$2346)),G2346) -> tier - 1 | N2346: =MATCH($H$4:$H$2346,$H$4:$H$2346,0) -> 1 | O2346: =IF(H2346="?",INDEX($H$4:$H$2346,MODE($N$4:$N$2346)),H2346) -> tier - 3 | P2346: =IF(I2346="?","Unknown",I2346) -> R1013 | Q2346: =CONCATENATE(D2346,"-",K2346,"-",J2346) -> 12-Oct-1968 | R2346: 25123 | S2346: =ROUND((($S$2-R2346)/365),0) -> 55 | T2346: 63770.43 | U2346: Id1 | V2346: 25123 | W2346: 0 | X2346: 63770.43 | Y2346: tier - 1 | Z2346: tier - 3 | AA2346: R1013 | AB2346: 55
A2347: =COUNTA(A4:A2346) -> 2343

Sheet Customer Names Transform
A1: Customer ID | B1: Last Name | C1: Title | D1: First Name
A2: Id1 | B2: Hawks | C2: Ms. | D2: Kelly
A3: Id2 | B3: Lehner | C3: Mr. | D3: Matthew D
A4: Id3 | B4: Lu | C4: Mr. | D4: Phil
A5: Id4 | B5: Osborne | C5: Ms. | D5: Kelsey
A6: Id5 | B6: Kadala | C6: Ms. | D6: Kristyn
A7: Id6 | B7: Baker | C7: Mr. | D7: Russell B.
A8: Id7 | B8: Macpherson | C8: Mr. | D8: Scott
A9: Id8 | B9: Hallman | C9: Mr. | D9: Stephen
A10: Id9 | B10: Moran | C10: Mr. | D10: Patrick R.
A11: Id10 | B11: Benner | C11: Ms. | D11: Brooke N.
A12: Id11 | B12: Fierro Vargas | C12: Ms. | D12: Paola Andrea
... A2336: Id2335 | B2336: German | C2336: Mr. | D2336: Aaron K

Sheet Medical Exam Transform
A1: Customer ID | B1: BMI | C1: HBA1C | D1: Heart Issues | E1: Any Transplants | F1: Cancer history | G1: NumberOfMajorSurgeries | H1: smoker | I1: Weight Status | J1: Diabetes Status
A2: Id1 | B2: 47.41 | C2: 7.47 | D2: No | E2: No | F2: No | G2: 0 | H2: Yes | I2: Obesity | J2: Diabetes
A3: Id2 | B3: 30.36 | C3: 5.77 | D3: No | E3: No | F3: No | G3: 0 | H3: Yes | I3: Obesity | J3: Prediabetes
A4: Id3 | B4: 34.485 | C4: 11.87 | D4: Yes | E4: No | F4: No | G4: 2 | H4: Yes | I4: Obesity | J4: Normal
A5: Id4 | B5: 38.095 | C5: 6.05 | D5: No | E5: No | F5: No | G5: 0 | H5: Yes | I5: Obesity | J5: Prediabetes
A6: Id5 | B6: 35.53 | C6: 5.45 | D6: No | E6: No | F6: No | G6: 0 | H6: Yes | I6: Obesity | J6: Prediabetes
A7: Id6 | B7: 32.8 | C7: 6.59 | D7: No | E7: No | F7: No | G7: 0 | H7: Yes | I7: Obesity | J7: Diabetes
A8: Id7 | B8: 36.4 | C8: 6.07 | D8: No | E8: No | F8: No | G8: 0 | H8: Yes | I8: Obesity | J8: Prediabetes
A9: Id8 | B9: 36.96 | C9: 7.93 | D9: No | E9: No | F9: No | G9: 3 | H9: Yes | I9: Obesity | J9: Diabetes
A10: Id9 | B10: 41.14 | C10: 9.58 | D10: Yes | E10: No | F10: Yes | G10: 1 | H10: Yes | I10: Obesity | J10: Diabetes
A11: Id10 | B11: 38.06 | C11: 10.79 | D11: No | E11: No | F11: No | G11: 0 | H11: Yes | I11: Obesity | J11: Diabetes
A12: Id11 | B12: 37.7 | C12: 5.96 | D12: Yes | E12: No | F12: No | G12: 2 | H12: Yes | I12: Obesity | J12: Normal
A13: Id12 | B13: 42.13 | C13: 11.9 | D13: No | E13: No | F13: No | G13: 0 | H13: Yes | I13: Obesity | J13: Normal
... A2336: Id2335 | B2336: 17.58 | C2336: 4.51 | D2336: No | E2336: No | F2336: No | G2336: 1 | H2336: No | I2336: Underweight | J2336: Normal

Sheet Hospitalisation Transform
A1: Customer ID | B1: Date Of Birth | C1: children | D1: charges | E1: Hospital tier | F1: City tier | G1: State ID | H1: Customer Age
A2: Id2335 | B2: 33794 | C2: 0 | D2: 563.84 | E2: tier - 2 | F2: tier - 3 | G2: R1013 | H2: 31
A3: Id2334 | B3: 33938 | C3: 0 | D3: 570.62 | E3: tier - 2 | F3: tier - 1 | G3: R1013 | H3: 31
A4: Id2333 | B4: 34150 | C4: 0 | D4: 600 | E4: tier - 2 | F4: tier - 1 | G4: R1013 | H4: 30
A5: Id2332 | B5: 33860 | C5: 0 | D5: 604.54 | E5: tier - 3 | F5: tier - 3 | G5: R1013 | H5: 31
A6: Id2331 | B6: 36003 | C6: 0 | D6: 637.26 | E6: tier - 3 | F6: tier - 3 | G6: R1013 | H6: 25
A7: Id2330 | B7: 37215 | C7: 0 | D7: 646.14 | E7: tier - 3 | F7: tier - 3 | G7: R1012 | H7: 22
A8: Id2329 | B8: 34121 | C8: 0 | D8: 650 | E8: tier - 3 | F8: tier - 3 | G8: R1013 | H8: 30
A9: Id2328 | B9: 34884 | C9: 0 | D9: 650 | E9: tier - 3 | F9: tier - 3 | G9: R1013 | H9: 28
A10: Id2327 | B10: 37589 | C10: 0 | D10: 668 | E10: tier - 3 | F10: tier - 2 | G10: R1012 | H10: 21
A11: Id2326 | B11: 35743 | C11: 0 | D11: 670 | E11: tier - 3 | F11: tier - 3 | G11: R1013 | H11: 26
A12: Id2325 | B12: 37146 | C12: 0 | D12: 687.54 | E12: tier - 3 | F12: tier - 2 | G12: R1013 | H12: 22
A13: Id2324 | B13: 36520 | C13: 0 | D13: 700 | E13: tier - 2 | F13: tier - 3 | G13: R1013 | H13: 23
... A2344: Id1 | B2344: 25123 | C2344: 0 | D2344: 63770.43 | E2344: tier - 1 | F2344: tier - 3 | G2344: R1013 | H2344: 55

Sheet  Health care Acitivity 1
A1: XLOOKUP(A3,'Customer Names'!$A$3:$A$2337,'Customer Names'!$E$3:$E$2337)
A2: Customer ID | B2: First name | C2: BMI | D2: HBA1C | E2: Heart Issues | F2: Any Transplants | G2: Cancer History | H2: Number of major Surgeries | I2: Smoker | J2: Weight Status | K2: Diabetes Status | L2: Date of Birth | M2: Charges | N2: Hospital Tier | O2: City Tier | P2: State ID | Q2: Age
A3: Id1 | B3: =_xlfn.XLOOKUP(A3,'Customer Names Transform'!$A$2:$A$2336,'Customer Names Transform'!$D$2:$D$2336) -> Kelly | C3: =_xlfn.XLOOKUP(A3,'Medical Exam Transform'!$A$2:$A$2336,'Medical Exam Transform'!$B$2:$B$2336) -> 47.41 | D3: =_xlfn.XLOOKUP(A3,'Medical Exam Transform'!$A$2:$A$2336,'Medical Exam Transform'!$C$2:$C$2336) -> 7.47 | E3: =_xlfn.XLOOKUP(A3,'Medical Exam Transform'!$A$2:$A$2336,'Medical Exam Transform'!$D$2:$D$2336) -> No | F3: =_xlfn.XLOOKUP(A3,'Medical Exam Transform'!$A$2:$A$2336,'Medical Exam Transform'!$E$2:$E$2336) -> No | G3: =_xlfn.XLOOKUP(A3,'Medical Exam Transform'!$A$2:$A$2336,'Medical Exam Transform'!$F$2:$F$2336) -> No | H3: =_xlfn.XLOOKUP(A3,'Medical Exam Transform'!$A$2:$A$2336,'Medical Exam Transform'!$G$2:$G$2336) -> 0 | I3: =_xlfn.XLOOKUP(A3,'Medical Exam Transform'!$A$2:$A$2336,'Medical Exam Transform'!$H$2:$H$2336) -> Yes | J3: =_xlfn.XLOOKUP(A3,'Medical Exam Transform'!$A$2:$A$2336,'Medical Exam Transform'!$I$2:$I$2336) -> Obesity | K3: =_xlfn.XLOOKUP(A3,'Medical Exam Transform'!$A$2:$A$2336,'Medical Exam Transform'!$J$2:$J$2336) -> Diabetes | L3: =_xlfn.XLOOKUP(A3,'Hospitalisation Transform'!$A$2:$A$2344,'Hospitalisation Transform'!$B$2:$B$2344) -> 25123 | M3: =_xlfn.XLOOKUP(A3,'Hospitalisation Transform'!$A$2:$A$2344,'Hospitalisation Transform'!$D$2:$D$2344) -> 63770.43 | N3: =_xlfn.XLOOKUP(A3,'Hospitalisation Transform'!$A$2:$A$2344,'Hospitalisation Transform'!$E$2:$E$2344) -> tier - 1 | O3: =_xlfn.XLOOKUP(A3,'Hospitalisation Transform'!$A$2:$A$2344,'Hospitalisation Transform'!$F$2:$F$2344) -> tier - 3 | P3: =_xlfn.XLOOKUP(A3,'Hospitalisation Transform'!$A$2:$A$2344,'Hospitalisation Transform'!$G$2:$G$2344) -> R1013 | Q3: =_xlfn.XLOOKUP(A3,'Hospitalisation Transform'!$A$2:$A$2344,'Hospitalisation Transform'!$H$2:$H$2344) -> 55
A4: Id2 | B4: =_xlfn.XLOOKUP(A4,'Customer Names Transform'!$A$2:$A$2336,'Customer Names Transform'!$D$2:$D$2336) -> Matthew D | C4: =_xlfn.XLOOKUP(A4,'Medical Exam Transform'!$A$2:$A$2336,'Medical Exam Transform'!$B$2:$B$2336) -> 30.36 | D4: =_xlfn.XLOOKUP(A4,'Medical Exam Transform'!$A$2:$A$2336,'Medical Exam Transform'!$C$2:$C$2336) -> 5.77 | E4: =_xlfn.XLOOKUP(A4,'Medical Exam Transform'!$A$2:$A$2336,'Medical Exam Transform'!$D$2:$D$2336) -> No | F4: =_xlfn.XLOOKUP(A4,'Medical Exam Transform'!$A$2:$A$2336,'Medical Exam Transform'!$E$2:$E$2336) -> No | G4: =_xlfn.XLOOKUP(A4,'Medical Exam Transform'!$A$2:$A$2336,'Medical Exam Transform'!$F$2:$F$2336) -> No | H4: =_xlfn.XLOOKUP(A4,'Medical Exam Transform'!$A$2:$A$2336,'Medical Exam Transform'!$G$2:$G$2336) -> 0 | I4: =_xlfn.XLOOKUP(A4,'Medical Exam Transform'!$A$2:$A$2336,'Medical Exam Transform'!$H$2:$H$2336) -> Yes | J4: =_xlfn.XLOOKUP(A4,'Medical Exam Transform'!$A$2:$A$2336,'Medical Exam Transform'!$I$2:$I$2336) -> Obesity | K4: =_xlfn.XLOOKUP(A4,'Medical Exam Transform'!$A$2:$A$2336,'Medical Exam Transform'!$J$2:$J$2336) -> Prediabetes | L4: =_xlfn.XLOOKUP(A4,'Hospitalisation Transform'!$A$2:$A$2344,'Hospitalisation Transform'!$B$2:$B$2344) -> 28284 | M4: =_xlfn.XLOOKUP(A4,'Hospitalisation Transform'!$A$2:$A$2344,'Hospitalisation Transform'!$D$2:$D$2344) -> 62592.87 | N4: =_xlfn.XLOOKUP(A4,'Hospitalisation Transform'!$A$2:$A$2344,'Hospitalisation Transform'!$E$2:$E$2344) -> tier - 2 | O4: =_xlfn.XLOOKUP(A4,'Hospitalisation Transform'!$A$2:$A$2344,'Hospitalisation Transform'!$F$2:$F$2344) -> tier - 3 | P4: =_xlfn.XLOOKUP(A4,'Hospitalisation Transform'!$A$2:$A$2344,'Hospitalisation Transform'!$G$2:$G$2344) -> R1013 | Q4: =_xlfn.XLOOKUP(A4,'Hospitalisation Transform'!$A$2:$A$2344,'Hospitalisation Transform'!$H$2:$H$2344) -> 46
